Workbook

Sheet 0. Mode d'emploi
A1: Outil de diagnostic - Guide d'utilisateur
A3: 1. Introduction
A25: 2. Utilisation de l'outil
A71: Fin du mode d'emploi

Sheet 1. Questionnaire d'entretien 
R1: Notes & Réponses
E2: Grille d'entretien | F2: Profil des interviewés (mettez un "x" dans la case pour identifier le ou les profils à interroger pour chaque question) | M2: Grille de notation | R2: Réponse 1 | T2: Réponse 2
A3: N° | B3: Niveau | C3: Dimension | D3: Thématique | E3: Question | F3: Profil 1 | G3: Profil 2 | H3: Profil 3 | I3: Profil 4 | J3: Profil 5 | K3: Profil 6 | L3: … (à compléter par la collectivité) | M3: 0 | N3: 1 | O3: 2 | P3: 3 | Q3: 4 | R3: Note (0 à 4, ou N/A) | S3: Réponse aux questions ouvertes / Commentaire | T3: Note (0 à 4, ou N/A) | U3: Réponse aux questions ouvertes / Commentaire
A4: 1 | B4: 1 | C4: 1. Stratégie et Gouvernance | D4: Stratégie globale | E4: L'engagement environnemental et sociétal fait-il partie des valeurs de la collectivité ? | M4: Non | N4: Il s'agit d'un centre d'intérêt de certains agents uniquement mais pas d'une valeur de la collectivité | O4: Il s'agit d'un centre d'intérêt de la plupart des agents mais pas d'une valeur de la collectivité | P4: C'est une valeur secondaire de la collectivité | Q4: C'est une valeur principale de la collectivité
A5: =A4+1 -> 2 | B5: 1 | C5: 1. Stratégie et Gouvernance | D5: Stratégie NR | E5: Avez-vous déjà intégré une dimension écologique à la gestion du numérique dans votre organisation ? | M5: Non | N5: Des initiatives indépendantes/non coordonnées ont été lancées au sein de la DSI seulement | O5: Des initiatives indépendantes/non coordonnées ont été lancées dans certaines directions de la collectivité | P5: Plusieurs initiatives existent et une démarche globale est en cours de définition/lancement | Q5: Une démarche stratégique globale a été lancée et a atteint de premiers objectifs
A6: =A5+1 -> 3 | B6: 1 | C6: 1. Stratégie et Gouvernance | D6: Stratégie NR | E6: Des objectifs de réduction d'impact environnemental du numérique ont-ils été définis ? | M6: Non | N6: Non, mais c'est en cours de définition | O6: Des objectifs spécifiques sont définis mais ils ne sont pas suivis | P6: Des objectifs spécifiques sont définis et suivis dans le cadre d'une démarche RSE centrale | Q6: Des objectifs spécifiques sont définis et suivis au niveau du pôle numérique responsable
A7: =A6+1 -> 4 | B7: 1 | C7: 1. Stratégie et Gouvernance | D7: Stratégie NR | E7: Quelle serait la principale raison qui vous motiverait à inclure des principes Numérique responsable au sein de la collectivité ? | M7: Aucune raison particulière | N7: Lancer une dynamique numérique responsable au sein de la collectivité | O7: Dès à présent répondre aux obligations réglementaires d'ici 2025 | P7: Construire une image plus positive de la collectivité auprès des citoyens, au-delà des obligations réglementaires | Q7: Devenir un acteur actif et leader de changement sociétal, au au-delà des obligations réglementaires et des images à renforcer
A8: =A7+1 -> 5 | B8: 2 | C8: 1. Stratégie et Gouvernance | D8: Stratégie NR | E8: Pilotez-vous des indicateurs de mesure spécifique au numérique responsable ? | M8: Non | N8: Non, mais souhaite le faire | O8: Non, mais en cours de mise en place | P8: Certains indicateurs sont mis en place et pilotés, mais pas pour l'ensemble des activités liées au numérique | Q8: Les indicateurs de mesure sont mis en place et pilotés pour l'ensemble des activités liées au numérique
A9: =A8+1 -> 6 | B9: 1 | C9: 1. Stratégie et Gouvernance | D9: Stratégie NR | E9: La stratégie numérique responsable de la collectivité est-elle déclinée dans chaque direction (DSI, achats, métiers…) ? | M9: Non | N9: Des consignes génériques sont définies au niveau NR et suivies seulement au sein de la DSI | O9: Des consignes génériques sont définies au niveau NR et suivies par les entités | P9: Des objectifs et consignes spécifiques à chaque entités sont définies au niveau NR | Q9: Des objectifs sont définis pour chaque entité au niveau NR, les entités définissent chacune leur stratégie NR
A10: =A9+1 -> 7 | B10: 1 | C10: 1. Stratégie et Gouvernance | D10: Stratégie NR | E10: La stratégie numérique responsable a-t-elle été déclinée dans d'autres documents programmatiques (SPASER, PCAET…) ? | M10: Non | N10: Non, mais en projet | O10: Oui, partiellement | P10: Oui, en grande partie | Q10: Oui ils sont totalement inclus
A11: =A10+1 -> 8 | B11: 1 | C11: 1. Stratégie et Gouvernance | D11: Stratégie NR | E11: Avez-vous un budget spécifique dédié pour une stratégie et des actions Numérique Responsable ? | M11: Non, pas de budget dédié au Numérique Responsable | N11: Budget limité et réparti dans différentes directions (DSI, direction de la transition écologique, etc.) | O11: Budget limité mais dédié au Numérique Responsable | P11: Budget important mais réparti dans différentes directions (DSI, direction de la transition écologique, etc.) | Q11: Budget important dédié au Numérique Responsable
A12: =A11+1 -> 9 | B12: 2 | C12: 1. Stratégie et Gouvernance | D12: Stratégie NR | E12: Comment est réparti le budget Numérique responsable (formations, développement de use cases, territoire connecté et durable, autres) ?
A13: =A12+1 -> 10 | B13: 3 | C13: 1. Stratégie et Gouvernance | D13: Stratégie NR | E13: Votre stratégie Numérique Responsable a-t-elle permis la mise en place de partenariats, la signature d'accords ou l'attribution de certifications / prix ? | M13: Non | N13: Non mais en cours d'identification d'opportunités | O13: Non mais certaines opportunités ont été identifiées pour la mise en place de partenariats / accords | P13: La collectivité a mis en place des partenariats ou s'est déjà engagée via des accords sur sa stratégie NR | Q13: La collectivité a été distinguée par des certifications / prix sur son investissement NR
A14: =A13+1 -> 11 | B14: 3 | C14: 1. Stratégie et Gouvernance | D14: Stratégie NR | E14: Si oui, décrivez les partenariats, accords ou certifications
A15: =A14+1 -> 12 | B15: 2 | C15: 1. Stratégie et Gouvernance | D15: Stratégie NR | E15: Des objectifs de Numérique responsable sont-ils intégrés à vos rapport annuels ? | M15: Non | N15: Non, mais c'est prévu à court terme | O15: Oui, partiellement (inclus dans les objectifs et la stratégie de l'organisation, mais pas détaillé dans la partie comptabilité) | P15: Oui, en grande partie (inclus dans les objectifs et la stratégie de de l'organisation et partiellement inclus dans la partie comptabilité) | Q15: Oui ils sont totalement inclus dans les rapports annuels (ils font intégralement partie des bilans financiers consolidés, ils sont définis dans les objectifs de l'organisation et ils ont leur propre partie dans le rapport annuel de l'organisation)
A16: =A15+1 -> 13 | B16: 2 | C16: 1. Stratégie et Gouvernance | D16: Stratégie NR | E16: Si oui, décrivez les éléments essentiels et l'année de mise en œuvre ?
A17: =A16+1 -> 14 | B17: 1 | C17: 1. Stratégie et Gouvernance | D17: Org. Interne | E17: Dans quelle fonction de la collectivité la dimension écologique du numérique est intégrée ? | M17: N'est pas intégrée | N17: Sera intégrée dans une des fonctions de la collectivité dans un futur proche | O17: Une fonction DSI | P17: Une fonction "Transition écologique" attachée au DGS | Q17: Une fonction transverse rattachée au DGS
A18: =A17+1 -> 15 | B18: 1 | C18: 1. Stratégie et Gouvernance | D18: Org. Interne | E18: Qui est en charge de porter les sujets Numérique Responsable au sein de votre organisation ? | M18: Personne n'est en charge | N18: Une personne porte ces sujets au sein d'une direction à temps partiel | O18: Une personne porte ces sujets au sein d'une direction à temps plein | P18: Une personne porte ces sujets au sein d'une direction à temps plein et elle dispose d'une équipe de contributeurs à temps partiel | Q18: Plusieurs personnes occupent un poste à temps plein dédié au Numérique Responsable
A19: =A18+1 -> 16 | B19: 2 | C19: 1. Stratégie et Gouvernance | D19: Org. Interne | E19: A quel niveau hiérarchique se situe le pôle Numérique Responsable ? | M19: Pas de pôle Numérique Responsable | N19: Le pôle Numérique Responsable n'est pas visible dans la hiérarchie | O19: Le pôle Numérique Responsable est rattaché au niveau d'une sous-direction de la DSI ou d'une autre direction | P19: Le pôle Numérique Responsable est rattaché au niveau de la DSI ou d'une autre direction | Q19: Le pôle Numérique Responsable est rattaché au niveau du DGS / de la Direction générale
A20: =A19+1 -> 17 | B20: 2 | C20: 1. Stratégie et Gouvernance | D20: Org. Interne | E20: Le responsable numérique responsable participe t-il à des comités de pilotage stratégiques au sein de la collectivité ? | M20: Non | N20: Non, mais c'est prévu à court terme | O20: Oui, en interne de son service | P20: Oui, en interne de sa direction | Q20: Oui, en transverse sur l'ensemble de la collectivité
A21: =A20+1 -> 18 | B21: 2 | C21: 1. Stratégie et Gouvernance | D21: Org. Interne | E21: Le pôle Numérique Responsable peut il s'appuyer sur des relais identifiés dans les directions ? | M21: Non | N21: Les personnes sont déjà identifiées mais peu d'échanges ont été menés avec elles sur le sujet du NR | O21: Un groupe de contacts permet de partager quelques informations avec le pôle Numérique Responsable (veille, …) | P21: Des relais diffusent une veille et des bonnes pratiques Numérique Responsable au sein des entités | Q21: Des représentants officiels (champions) du numérique responsable sont identifiés dans les différentes entités et ont une charge dédiée à cette thématique
A22: =A21+1 -> 19 | B22: 3 | C22: 1. Stratégie et Gouvernance | D22: Org. Interne | E22: Faites-vous appel à des prestataires spécialisés dans le Numérique Responsable ? | M22: Non | N22: Non, mais c'est prévu à court terme | O22: Des prestataires potentiels ont déjà été identifiés | P22: Des discussions ont été engagées avec des prestataires potentiels | Q22: Des prestataires ont déjà été sollicités pour accompagner la collectivité
A23: =A22+1 -> 20 | B23: 2 | C23: 1. Stratégie et Gouvernance | D23: AVEC/BYOD | E23: Mettez-vous en place une stratégie "AVEC/BYOD" (Apportez Votre Equipement personnel de Communication/Bring Your Own Device) pour l'équipement informatique type ordinateur portable ? | M23: Non, ne souhaite pas le faire | N23: Non, mais souhaite le faire | O23: Non, mais une réflexion a déjà été engagée | P23: Oui, en cours de mise en place | Q23: Oui, déjà mis en place
A24: =A23+1 -> 21 | B24: 2 | C24: 1. Stratégie et Gouvernance | D24: AVEC/BYOD | E24: Mettez-vous en place une stratégie "AVEC/BYOD" (Apportez Votre Equipement personnel de Communication/Bring Your Own Device) pour l'équipement téléphonique type smartphone ? | M24: Non, ne souhaite pas le faire | N24: Non, mais souhaite le faire | O24: Non, mais une réflexion a déjà été engagée | P24: Oui, en cours de mise en place | Q24: Oui, déjà mis en place
A25: =A24+1 -> 22 | B25: 2 | C25: 1. Stratégie et Gouvernance | D25: AVEC/BYOD | E25: En cas d'application d'une stratégie "AVEC", quelle stratégie avez-vous mis en place pour la faire accepter par les agents ?
A26: =A25+1 -> 23 | B26: 2 | C26: 1. Stratégie et Gouvernance | D26: Mesure d'impact environnemental | E26: Quel est le niveau d’urgence de votre besoin en outils ou méthodologies de mesure ? (Faible / Moyen / élevé)
A27: =A26+1 -> 24 | B27: 2 | C27: 1. Stratégie et Gouvernance | D27: Mesure d'impact environnemental | E27: Quelles sont vos priorités ? (Se faire accompagner / Se former / Outiller / Mesurer / Suivre / etc.)
A28: =A27+1 -> 25 | B28: 1 | C28: 1. Stratégie et Gouvernance | D28: Reporting | E28: Disposez-vous d'un outil de suivi et de pilotage de la performance environnementale du SI ? | M28: Non, ne souhaite pas le faire | N28: Non, mais souhaite le faire à court terme | O28: Non, mais en cours de mise en place | P28: Oui, mais l'outil est très peu utilisé | Q28: Oui, la performance environnementale du SI est suivi et piloté à l'aide d'un outil
A29: =A28+1 -> 26 | B29: 1 | C29: 1. Stratégie et Gouvernance | D29: Sources | E29: De quelles sources proviennent les bonnes pratiques liées au Numérique Responsable mises en place par la collectivité (réglementation, organismes d'autorité, propres initiatives…)? | M29: Aucune source identifiée | N29: La collectivité applique principalement la réglementation | O29: La collectivité s'appuie sur les préconisations d'organismes reconnus comme l'ADEME, le club Green IT… | P29: La collectivité participe à des démarches exploratoires sur certains leviers | Q29: La collectivité expérimente des leviers et fait figure de précurseur
A30: =A29+1 -> 27 | B30: 1 | C30: 1. Stratégie et Gouvernance | D30: Déploiement | E30: Pourriez-vous fournir des exemples de mesures/projets/initiatives mis en place concernant le Numérique responsable ?
A31: =A30+1 -> 28 | B31: 1 | C31: 2. Mesure | D31: Empreinte environnementale du SI | E31: L'empreinte environnementale de votre SI, ou de votre projet, a-t-elle été évaluée au moins une fois ? | M31: Non | N31: Non, mais en projet | O31: Une fois | P31: Ponctuellement | Q31: Suivi régulier
A32: =A31+1 -> 29 | B32: 3 | C32: 2. Mesure | D32: Empreinte environnementale du SI | E32: Quels indicateurs sont suivis pour l'évaluation de votre empreinte environnementale du SI ?
A33: =A32+1 -> 30 | B33: 3 | C33: 2. Mesure | D33: Empreinte environnementale du SI | E33: Quels référentiels ou base de données environnementaux utilisez-vous pour faire cette évaluation ?
A34: =A33+1 -> 31 | B34: 3 | C34: 2. Mesure | D34: Empreinte environnementale du SI | E34: Avez-vous mesuré cette empreinte en interne par la collectivité ou en ayant recours à un bureau d'étude spécialisé ?
A35: =A34+1 -> 32 | B35: 3 | C35: 2. Mesure | D35: Empreinte environnementale du SI | E35: Utilisez-vous le RGESN (Référentiel général d'écoconception de services numériques) ? Le protocole GHG (protocole international proposant un cadre pour mesurer, comptabiliser et gérer les émissions de gaz à effet de serre) ? | M35: Non, ne connaît pas | N35: Non, mais connu | O35: Non, mais en cours de mise en place | P35: Oui, mais peu utilisé | Q35: Oui, utilisé
A36: =A35+1 -> 33 | B36: 1 | C36: 2. Mesure | D36: Empreinte environnementale du SI | E36: Etes-vous familier avec l'Analyse du Cycle de Vie (ACV) ? | M36: Non, ne connaît pas | N36: Non, mais connu | O36: Oui, mais peu utilisé | P36: Oui, utilisé | Q36: Oui, utilisé et maitrisé pour effectuer des calculs d'empreinte environnemental de l'IT
A37: =A36+1 -> 34 | B37: 2 | C37: 2. Mesure | D37: Empreinte environnementale du SI | E37: Si vous évaluez l'empreinte environnemental de votre SI, avez-vous une stratégie de mesure basée sur une ACV (analyse du cycle de vie) ? | M37: Non | N37: Non, mais une réflexion a été engagée | O37: Non, mais la stratégie sera mise en place à court terme | P37: Oui, les calculs sont déjà basés sur la méthodologie AVC | Q37: Oui, les calculs sont déjà basés sur la méthodologie AVC et certains agents maitrisent son utilisation
A38: =A37+1 -> 35 | B38: 2 | C38: 2. Mesure | D38: Empreinte environnementale du SI | E38: Si oui, précisez le contenu de cette stratégie avec ACV ?
A39: =A38+1 -> 36 | B39: 1 | C39: 2. Mesure | D39: Empreinte environnementale du SI | E39: Avez-vous réalisé un bilan carbone ? | M39: Non | N39: Non, mais prévu de le faire à court terme | O39: Non, mais en cours de réalisation | P39: Oui, mais incomplet et non suivi d'actions | Q39: Oui, régulièrement et inséré dans une stratégie de la CT
A40: =A39+1 -> 37 | B40: 1 | C40: 2. Mesure | D40: Empreinte environnementale du SI | E40: Publiez-vous votre BEGES (Décret bilan des émissions de gaz à effet de serre) ? | M40: Non | N40: Non, mais prévu de le faire à court terme | O40: Non, mais en cours de réalisation | P40: Oui, ponctuellement | Q40: Oui, régulièrement et inséré dans une stratégie de la CT
...

Sheet 2. Note de maturité
B1: Calcul des notes par question | I1: Calcul des notes par dimension | N1: Note de maturité par dimension
B3: N° | C3: Note 1 | D3: Note 2 | E3: Note moyenne | F3: Pondération | G3: Note pondérée | I3: Dimension | J3: Somme note pondérée | K3: Somme pondération | L3: Note pondérée | N3: Dimension | O3: Note de maturité
B4: 1 | C4: =IF('1. Questionnaire d''entretien '!R4="","N/A",'1. Questionnaire d''entretien '!R4) -> N/A | D4: =IF('1. Questionnaire d''entretien '!T4="","N/A",'1. Questionnaire d''entretien '!T4) -> N/A | E4: =IF(AND(C4="N/A",D4="N/A"),"N/A",AVERAGE(C4:D4)) -> N/A | F4: {=_xlfn.IFS('1. Questionnaire d''entretien '!B4=1,1,'1. Questionnaire d''entretien '!B4=2,0.75,'1. Questionnaire d''entretien '!B4=3,0.5)} -> 1 | G4: =IF(E4="N/A","N/A",E4*F4) -> N/A | I4: 1. Stratégie et Gouvernance | J4: =SUMIF('1. Questionnaire d''entretien '!$C$4:$C$215,I4,'2. Note de maturité'!$G$4:$G$215) -> 0 | K4: =SUMIFS($F$4:$F$215,'1. Questionnaire d''entretien '!$C$4:$C$215,'2. Note de maturité'!I4,'2. Note de maturité'!$E$4:$E$215,"<>N/A") -> 0 | L4: =J4/K4 -> #DIV/0! | N4: 1. Stratégie et Gouvernance | O4: =IF(ISNUMBER(L4),L4,"N/A") -> N/A
B5: =B4+1 -> 2 | C5: =IF('1. Questionnaire d''entretien '!R5="","N/A",'1. Questionnaire d''entretien '!R5) -> N/A | D5: =IF('1. Questionnaire d''entretien '!T5="","N/A",'1. Questionnaire d''entretien '!T5) -> N/A | E5: =IF(AND(C5="N/A",D5="N/A"),"N/A",AVERAGE(C5:D5)) -> N/A | F5: {=_xlfn.IFS('1. Questionnaire d''entretien '!B5=1,1,'1. Questionnaire d''entretien '!B5=2,0.75,'1. Questionnaire d''entretien '!B5=3,0.5)} -> 1 | G5: =IF(E5="N/A","N/A",E5*F5) -> N/A | I5: 2. Mesure | J5: =SUMIF('1. Questionnaire d''entretien '!$C$4:$C$215,I5,'2. Note de maturité'!$G$4:$G$215) -> 0 | K5: =SUMIFS($F$4:$F$215,'1. Questionnaire d''entretien '!$C$4:$C$215,'2. Note de maturité'!I5,'2. Note de maturité'!$E$4:$E$215,"<>N/A") -> 0 | L5: =J5/K5 -> #DIV/0! | N5: 2. Mesure | O5: =IF(ISNUMBER(L5),L5,"N/A") -> N/A
B6: =B5+1 -> 3 | C6: =IF('1. Questionnaire d''entretien '!R6="","N/A",'1. Questionnaire d''entretien '!R6) -> N/A | D6: =IF('1. Questionnaire d''entretien '!T6="","N/A",'1. Questionnaire d''entretien '!T6) -> N/A | E6: =IF(AND(C6="N/A",D6="N/A"),"N/A",AVERAGE(C6:D6)) -> N/A | F6: {=_xlfn.IFS('1. Questionnaire d''entretien '!B6=1,1,'1. Questionnaire d''entretien '!B6=2,0.75,'1. Questionnaire d''entretien '!B6=3,0.5)} -> 1 | G6: =IF(E6="N/A","N/A",E6*F6) -> N/A | I6: 3. Achat | J6: =SUMIF('1. Questionnaire d''entretien '!$C$4:$C$215,I6,'2. Note de maturité'!$G$4:$G$215) -> 0 | K6: =SUMIFS($F$4:$F$215,'1. Questionnaire d''entretien '!$C$4:$C$215,'2. Note de maturité'!I6,'2. Note de maturité'!$E$4:$E$215,"<>N/A") -> 0 | L6: =J6/K6 -> #DIV/0! | N6: 3. Achat | O6: =IF(ISNUMBER(L6),L6,"N/A") -> N/A
B7: =B6+1 -> 4 | C7: =IF('1. Questionnaire d''entretien '!R7="","N/A",'1. Questionnaire d''entretien '!R7) -> N/A | D7: =IF('1. Questionnaire d''entretien '!T7="","N/A",'1. Questionnaire d''entretien '!T7) -> N/A | E7: =IF(AND(C7="N/A",D7="N/A"),"N/A",AVERAGE(C7:D7)) -> N/A | F7: {=_xlfn.IFS('1. Questionnaire d''entretien '!B7=1,1,'1. Questionnaire d''entretien '!B7=2,0.75,'1. Questionnaire d''entretien '!B7=3,0.5)} -> 1 | G7: =IF(E7="N/A","N/A",E7*F7) -> N/A | I7: 4. Transformation de l'IT | J7: =SUMIF('1. Questionnaire d''entretien '!$C$4:$C$215,I7,'2. Note de maturité'!$G$4:$G$215) -> 0 | K7: =SUMIFS($F$4:$F$215,'1. Questionnaire d''entretien '!$C$4:$C$215,'2. Note de maturité'!I7,'2. Note de maturité'!$E$4:$E$215,"<>N/A") -> 0 | L7: =J7/K7 -> #DIV/0! | N7: 4. Transformation de l'IT | O7: =IF(ISNUMBER(L7),L7,"N/A") -> N/A
B8: =B7+1 -> 5 | C8: =IF('1. Questionnaire d''entretien '!R8="","N/A",'1. Questionnaire d''entretien '!R8) -> N/A | D8: =IF('1. Questionnaire d''entretien '!T8="","N/A",'1. Questionnaire d''entretien '!T8) -> N/A | E8: =IF(AND(C8="N/A",D8="N/A"),"N/A",AVERAGE(C8:D8)) -> N/A | F8: {=_xlfn.IFS('1. Questionnaire d''entretien '!B8=1,1,'1. Questionnaire d''entretien '!B8=2,0.75,'1. Questionnaire d''entretien '!B8=3,0.5)} -> 0.75 | G8: =IF(E8="N/A","N/A",E8*F8) -> N/A | I8: 5. DEEE et Economie circulaire | J8: =SUMIF('1. Questionnaire d''entretien '!$C$4:$C$215,I8,'2. Note de maturité'!$G$4:$G$215) -> 0 | K8: =SUMIFS($F$4:$F$215,'1. Questionnaire d''entretien '!$C$4:$C$215,'2. Note de maturité'!I8,'2. Note de maturité'!$E$4:$E$215,"<>N/A") -> 0 | L8: =J8/K8 -> #DIV/0! | N8: 5. DEEE et Economie circulaire | O8: =IF(ISNUMBER(L8),L8,"N/A") -> N/A
B9: =B8+1 -> 6 | C9: =IF('1. Questionnaire d''entretien '!R9="","N/A",'1. Questionnaire d''entretien '!R9) -> N/A | D9: =IF('1. Questionnaire d''entretien '!T9="","N/A",'1. Questionnaire d''entretien '!T9) -> N/A | E9: =IF(AND(C9="N/A",D9="N/A"),"N/A",AVERAGE(C9:D9)) -> N/A | F9: {=_xlfn.IFS('1. Questionnaire d''entretien '!B9=1,1,'1. Questionnaire d''entretien '!B9=2,0.75,'1. Questionnaire d''entretien '!B9=3,0.5)} -> 1 | G9: =IF(E9="N/A","N/A",E9*F9) -> N/A | I9: 6. Sensibilisation | J9: =SUMIF('1. Questionnaire d''entretien '!$C$4:$C$215,I9,'2. Note de maturité'!$G$4:$G$215) -> 0 | K9: =SUMIFS($F$4:$F$215,'1. Questionnaire d''entretien '!$C$4:$C$215,'2. Note de maturité'!I9,'2. Note de maturité'!$E$4:$E$215,"<>N/A") -> 0 | L9: =J9/K9 -> #DIV/0! | N9: 6. Sensibilisation | O9: =IF(ISNUMBER(L9),L9,"N/A") -> N/A
B10: =B9+1 -> 7 | C10: =IF('1. Questionnaire d''entretien '!R10="","N/A",'1. Questionnaire d''entretien '!R10) -> N/A | D10: =IF('1. Questionnaire d''entretien '!T10="","N/A",'1. Questionnaire d''entretien '!T10) -> N/A | E10: =IF(AND(C10="N/A",D10="N/A"),"N/A",AVERAGE(C10:D10)) -> N/A | F10: {=_xlfn.IFS('1. Questionnaire d''entretien '!B10=1,1,'1. Questionnaire d''entretien '!B10=2,0.75,'1. Questionnaire d''entretien '!B10=3,0.5)} -> 1 | G10: =IF(E10="N/A","N/A",E10*F10) -> N/A | I10: 7. IT pour une Collectivité Eco-responsable | J10: =SUMIF('1. Questionnaire d''entretien '!$C$4:$C$215,I10,'2. Note de maturité'!$G$4:$G$215) -> 0 | K10: =SUMIFS($F$4:$F$215,'1. Questionnaire d''entretien '!$C$4:$C$215,'2. Note de maturité'!I10,'2. Note de maturité'!$E$4:$E$215,"<>N/A") -> 0 | L10: =J10/K10 -> #DIV/0! | N10: 7. IT pour une Collectivité Eco-responsable | O10: =IF(ISNUMBER(L10),L10,"N/A") -> N/A
B11: =B10+1 -> 8 | C11: =IF('1. Questionnaire d''entretien '!R11="","N/A",'1. Questionnaire d''entretien '!R11) -> N/A | D11: =IF('1. Questionnaire d''entretien '!T11="","N/A",'1. Questionnaire d''entretien '!T11) -> N/A | E11: =IF(AND(C11="N/A",D11="N/A"),"N/A",AVERAGE(C11:D11)) -> N/A | F11: {=_xlfn.IFS('1. Questionnaire d''entretien '!B11=1,1,'1. Questionnaire d''entretien '!B11=2,0.75,'1. Questionnaire d''entretien '!B11=3,0.5)} -> 1 | G11: =IF(E11="N/A","N/A",E11*F11) -> N/A
B12: =B11+1 -> 9 | C12: =IF('1. Questionnaire d''entretien '!R12="","N/A",'1. Questionnaire d''entretien '!R12) -> N/A | D12: =IF('1. Questionnaire d''entretien '!T12="","N/A",'1. Questionnaire d''entretien '!T12) -> N/A | E12: =IF(AND(C12="N/A",D12="N/A"),"N/A",AVERAGE(C12:D12)) -> N/A | F12: {=_xlfn.IFS('1. Questionnaire d''entretien '!B12=1,1,'1. Questionnaire d''entretien '!B12=2,0.75,'1. Questionnaire d''entretien '!B12=3,0.5)} -> 0.75 | G12: =IF(E12="N/A","N/A",E12*F12) -> N/A
B13: =B12+1 -> 10 | C13: =IF('1. Questionnaire d''entretien '!R13="","N/A",'1. Questionnaire d''entretien '!R13) -> N/A | D13: =IF('1. Questionnaire d''entretien '!T13="","N/A",'1. Questionnaire d''entretien '!T13) -> N/A | E13: =IF(AND(C13="N/A",D13="N/A"),"N/A",AVERAGE(C13:D13)) -> N/A | F13: {=_xlfn.IFS('1. Questionnaire d''entretien '!B13=1,1,'1. Questionnaire d''entretien '!B13=2,0.75,'1. Questionnaire d''entretien '!B13=3,0.5)} -> 0.5 | G13: =IF(E13="N/A","N/A",E13*F13) -> N/A | N13: Note de maturité globale
B14: =B13+1 -> 11 | C14: =IF('1. Questionnaire d''entretien '!R14="","N/A",'1. Questionnaire d''entretien '!R14) -> N/A | D14: =IF('1. Questionnaire d''entretien '!T14="","N/A",'1. Questionnaire d''entretien '!T14) -> N/A | E14: =IF(AND(C14="N/A",D14="N/A"),"N/A",AVERAGE(C14:D14)) -> N/A | F14: {=_xlfn.IFS('1. Questionnaire d''entretien '!B14=1,1,'1. Questionnaire d''entretien '!B14=2,0.75,'1. Questionnaire d''entretien '!B14=3,0.5)} -> 0.5 | G14: =IF(E14="N/A","N/A",E14*F14) -> N/A
B15: =B14+1 -> 12 | C15: =IF('1. Questionnaire d''entretien '!R15="","N/A",'1. Questionnaire d''entretien '!R15) -> N/A | D15: =IF('1. Questionnaire d''entretien '!T15="","N/A",'1. Questionnaire d''entretien '!T15) -> N/A | E15: =IF(AND(C15="N/A",D15="N/A"),"N/A",AVERAGE(C15:D15)) -> N/A | F15: {=_xlfn.IFS('1. Questionnaire d''entretien '!B15=1,1,'1. Questionnaire d''entretien '!B15=2,0.75,'1. Questionnaire d''entretien '!B15=3,0.5)} -> 0.75 | G15: =IF(E15="N/A","N/A",E15*F15) -> N/A | N15: =AVERAGE(O4:O10) -> #DIV/0!
B16: =B15+1 -> 13 | C16: =IF('1. Questionnaire d''entretien '!R16="","N/A",'1. Questionnaire d''entretien '!R16) -> N/A | D16: =IF('1. Questionnaire d''entretien '!T16="","N/A",'1. Questionnaire d''entretien '!T16) -> N/A | E16: =IF(AND(C16="N/A",D16="N/A"),"N/A",AVERAGE(C16:D16)) -> N/A | F16: {=_xlfn.IFS('1. Questionnaire d''entretien '!B16=1,1,'1. Questionnaire d''entretien '!B16=2,0.75,'1. Questionnaire d''entretien '!B16=3,0.5)} -> 0.75 | G16: =IF(E16="N/A","N/A",E16*F16) -> N/A
B17: =B16+1 -> 14 | C17: =IF('1. Questionnaire d''entretien '!R17="","N/A",'1. Questionnaire d''entretien '!R17) -> N/A | D17: =IF('1. Questionnaire d''entretien '!T17="","N/A",'1. Questionnaire d''entretien '!T17) -> N/A | E17: =IF(AND(C17="N/A",D17="N/A"),"N/A",AVERAGE(C17:D17)) -> N/A | F17: {=_xlfn.IFS('1. Questionnaire d''entretien '!B17=1,1,'1. Questionnaire d''entretien '!B17=2,0.75,'1. Questionnaire d''entretien '!B17=3,0.5)} -> 1 | G17: =IF(E17="N/A","N/A",E17*F17) -> N/A
B18: =B17+1 -> 15 | C18: =IF('1. Questionnaire d''entretien '!R18="","N/A",'1. Questionnaire d''entretien '!R18) -> N/A | D18: =IF('1. Questionnaire d''entretien '!T18="","N/A",'1. Questionnaire d''entretien '!T18) -> N/A | E18: =IF(AND(C18="N/A",D18="N/A"),"N/A",AVERAGE(C18:D18)) -> N/A | F18: {=_xlfn.IFS('1. Questionnaire d''entretien '!B18=1,1,'1. Questionnaire d''entretien '!B18=2,0.75,'1. Questionnaire d''entretien '!B18=3,0.5)} -> 1 | G18: =IF(E18="N/A","N/A",E18*F18) -> N/A
B19: =B18+1 -> 16 | C19: =IF('1. Questionnaire d''entretien '!R19="","N/A",'1. Questionnaire d''entretien '!R19) -> N/A | D19: =IF('1. Questionnaire d''entretien '!T19="","N/A",'1. Questionnaire d''entretien '!T19) -> N/A | E19: =IF(AND(C19="N/A",D19="N/A"),"N/A",AVERAGE(C19:D19)) -> N/A | F19: {=_xlfn.IFS('1. Questionnaire d''entretien '!B19=1,1,'1. Questionnaire d''entretien '!B19=2,0.75,'1. Questionnaire d''entretien '!B19=3,0.5)} -> 0.75 | G19: =IF(E19="N/A","N/A",E19*F19) -> N/A
B20: =B19+1 -> 17 | C20: =IF('1. Questionnaire d''entretien '!R20="","N/A",'1. Questionnaire d''entretien '!R20) -> N/A | D20: =IF('1. Questionnaire d''entretien '!T20="","N/A",'1. Questionnaire d''entretien '!T20) -> N/A | E20: =IF(AND(C20="N/A",D20="N/A"),"N/A",AVERAGE(C20:D20)) -> N/A | F20: {=_xlfn.IFS('1. Questionnaire d''entretien '!B20=1,1,'1. Questionnaire d''entretien '!B20=2,0.75,'1. Questionnaire d''entretien '!B20=3,0.5)} -> 0.75 | G20: =IF(E20="N/A","N/A",E20*F20) -> N/A
B21: =B20+1 -> 18 | C21: =IF('1. Questionnaire d''entretien '!R21="","N/A",'1. Questionnaire d''entretien '!R21) -> N/A | D21: =IF('1. Questionnaire d''entretien '!T21="","N/A",'1. Questionnaire d''entretien '!T21) -> N/A | E21: =IF(AND(C21="N/A",D21="N/A"),"N/A",AVERAGE(C21:D21)) -> N/A | F21: {=_xlfn.IFS('1. Questionnaire d''entretien '!B21=1,1,'1. Questionnaire d''entretien '!B21=2,0.75,'1. Questionnaire d''entretien '!B21=3,0.5)} -> 0.75 | G21: =IF(E21="N/A","N/A",E21*F21) -> N/A
B22: =B21+1 -> 19 | C22: =IF('1. Questionnaire d''entretien '!R22="","N/A",'1. Questionnaire d''entretien '!R22) -> N/A | D22: =IF('1. Questionnaire d''entretien '!T22="","N/A",'1. Questionnaire d''entretien '!T22) -> N/A | E22: =IF(AND(C22="N/A",D22="N/A"),"N/A",AVERAGE(C22:D22)) -> N/A | F22: {=_xlfn.IFS('1. Questionnaire d''entretien '!B22=1,1,'1. Questionnaire d''entretien '!B22=2,0.75,'1. Questionnaire d''entretien '!B22=3,0.5)} -> 0.5 | G22: =IF(E22="N/A","N/A",E22*F22) -> N/A
B23: =B22+1 -> 20 | C23: =IF('1. Questionnaire d''entretien '!R23="","N/A",'1. Questionnaire d''entretien '!R23) -> N/A | D23: =IF('1. Questionnaire d''entretien '!T23="","N/A",'1. Questionnaire d''entretien '!T23) -> N/A | E23: =IF(AND(C23="N/A",D23="N/A"),"N/A",AVERAGE(C23:D23)) -> N/A | F23: {=_xlfn.IFS('1. Questionnaire d''entretien '!B23=1,1,'1. Questionnaire d''entretien '!B23=2,0.75,'1. Questionnaire d''entretien '!B23=3,0.5)} -> 0.75 | G23: =IF(E23="N/A","N/A",E23*F23) -> N/A
B24: =B23+1 -> 21 | C24: =IF('1. Questionnaire d''entretien '!R24="","N/A",'1. Questionnaire d''entretien '!R24) -> N/A | D24: =IF('1. Questionnaire d''entretien '!T24="","N/A",'1. Questionnaire d''entretien '!T24) -> N/A | E24: =IF(AND(C24="N/A",D24="N/A"),"N/A",AVERAGE(C24:D24)) -> N/A | F24: {=_xlfn.IFS('1. Questionnaire d''entretien '!B24=1,1,'1. Questionnaire d''entretien '!B24=2,0.75,'1. Questionnaire d''entretien '!B24=3,0.5)} -> 0.75 | G24: =IF(E24="N/A","N/A",E24*F24) -> N/A
B25: =B24+1 -> 22 | C25: =IF('1. Questionnaire d''entretien '!R25="","N/A",'1. Questionnaire d''entretien '!R25) -> N/A | D25: =IF('1. Questionnaire d''entretien '!T25="","N/A",'1. Questionnaire d''entretien '!T25) -> N/A | E25: =IF(AND(C25="N/A",D25="N/A"),"N/A",AVERAGE(C25:D25)) -> N/A | F25: {=_xlfn.IFS('1. Questionnaire d''entretien '!B25=1,1,'1. Questionnaire d''entretien '!B25=2,0.75,'1. Questionnaire d''entretien '!B25=3,0.5)} -> 0.75 | G25: =IF(E25="N/A","N/A",E25*F25) -> N/A
B26: =B25+1 -> 23 | C26: =IF('1. Questionnaire d''entretien '!R26="","N/A",'1. Questionnaire d''entretien '!R26) -> N/A | D26: =IF('1. Questionnaire d''entretien '!T26="","N/A",'1. Questionnaire d''entretien '!T26) -> N/A | E26: =IF(AND(C26="N/A",D26="N/A"),"N/A",AVERAGE(C26:D26)) -> N/A | F26: {=_xlfn.IFS('1. Questionnaire d''entretien '!B26=1,1,'1. Questionnaire d''entretien '!B26=2,0.75,'1. Questionnaire d''entretien '!B26=3,0.5)} -> 0.75 | G26: =IF(E26="N/A","N/A",E26*F26) -> N/A
B27: =B26+1 -> 24 | C27: =IF('1. Questionnaire d''entretien '!R27="","N/A",'1. Questionnaire d''entretien '!R27) -> N/A | D27: =IF('1. Questionnaire d''entretien '!T27="","N/A",'1. Questionnaire d''entretien '!T27) -> N/A | E27: =IF(AND(C27="N/A",D27="N/A"),"N/A",AVERAGE(C27:D27)) -> N/A | F27: {=_xlfn.IFS('1. Questionnaire d''entretien '!B27=1,1,'1. Questionnaire d''entretien '!B27=2,0.75,'1. Questionnaire d''entretien '!B27=3,0.5)} -> 0.75 | G27: =IF(E27="N/A","N/A",E27*F27) -> N/A
... B215: =B214+1 -> 212 | C215: =IF('1. Questionnaire d''entretien '!R215="","N/A",'1. Questionnaire d''entretien '!R215) -> N/A | D215: =IF('1. Questionnaire d''entretien '!T215="","N/A",'1. Questionnaire d''entretien '!T215) -> N/A | E215: =IF(AND(C215="N/A",D215="N/A"),"N/A",AVERAGE(C215:D215)) -> N/A | F215: {=_xlfn.IFS('1. Questionnaire d''entretien '!B215=1,1,'1. Questionnaire d''entretien '!B215=2,0.75,'1. Questionnaire d''entretien '!B215=3,0.5)} -> 0.75 | G215: =IF(E215="N/A","N/A",E215*F215) -> N/A

Sheet 3. Glossaire
A1: Acronyme | B1: Signification
A2: ACV | B2: Analyse de Cycle de Vie
A3: AR | B3: Réalité Augmentée
A4: AVEC/BYOD | B4: Apportez Votre Equipement personnel de Communication/Bring Your Own Device
A5: CCTP | B5: Cahier des Clauses Techniques Particulières
A6: DEEE | B6: Déchets d’Equipements Electriques et Electroniques
A7: DINUM | B7: Direction interministérielle du numérique
A8: GES | B8: Gas à Effet de Serre
A9: IA | B9: Intelligence Artificielle
A10: INR | B10: Institut du Numérique Responsable
A11: IT | B11: Information Technology (Technologies de l'information)
A12: NR | B12: Numérique Responsable
... A18: VR | B18: Réalité Virtuelle

Sheet Validation des données
B2: Note
B3: 0
B4: 1
B5: 2
B6: 3
B7: 4
B8: N/A

Sheet 1. Stratégie et Gouvernance
A1: Grille d'entretien | G1: Grille de notation
A2: Niveau | B2: Pilier | C2: Thématique | D2: Question | E2: Types de réponses | F2: Acteur répondant | G2: 1 | H2: 2 | I2: 3 | J2: 4
A3: 1 | B3: 1. Stratégie et Gouvernance | C3: Stratégie globale | D3: L'engagement environnemental et sociétal fait-il partie des valeurs de la collectivité ? | G3: Non | H3: Il s'agit d'un centre d'intérêt des agents mais pas d'une valeur de la collectivité | I3: C'est une valeur secondaire de la collectivité | J3: C'est une valeur principale de la collectivité
A4: 1 | B4: 1. Stratégie et Gouvernance | C4: Stratégie NR | D4: Avez-vous déjà intégré une dimension écologique à la gestion du numérique dans votre organisation ? | G4: Non | H4: Des initiatives indépendantes/non coordonnées ont été lancées au sein de la DSI seulement | I4: Plusieurs initiatives existent et une démarche globale est en cours de définition/lancement | J4: Une démarche stratégique globale a été lancée et a atteint de premiers objectifs
A5: 1 | B5: 1. Stratégie et Gouvernance | C5: Stratégie NR | D5: Des objectifs de réduction d'impact environnemental du numérique ont-ils été définis ? | G5: Non | H5: Des objectifs spécifiques sont définis mais ils ne sont pas suivis | I5: Des objectifs spécifiques sont définis et suivis dans le cadre d'une démarche RSE centrale | J5: Des objectifs spécifiques sont définis et suivis au niveau du pôle numérique responsable
A6: 1 | B6: 1. Stratégie et Gouvernance | C6: Stratégie NR | D6: Quelle serait la principale raison qui vous motiverait à inclure des principes Numérique responsable au sein de la collectivité ? | G6: Aucune raison particulière | H6: Des raisons juridiques (l'obligation juridique de se conformer aux régulations environnementales) | I6: La motivation de construire une image plus positive de la collectivité | J6: Le souhait de devenir un acteur actif et leader de changement societal
A7: 2 | B7: 1. Stratégie et Gouvernance | C7: Stratégie NR | D7: Pilotez-vous des indicateurs de mesure spécifique au numérique responsable ? (label?)
A8: 1 | B8: 1. Stratégie et Gouvernance | C8: Stratégie NR | D8: La stratégie numérique responsable de l'entreprise est-elle déclinée dans chaque entité (DSI, achats, métiers…) ? | G8: Non | H8: Des consignes génériques sont définies au niveau NR et suivies par les entités | I8: Des objectifs et consignes spécifiques à chaque entités sont définies au niveau NR | J8: Des objectifs sont définis pour chaque entité au niveau NR, les entités définissent chacune leur stratégie NR
A9: 1 | B9: 1. Stratégie et Gouvernance | C9: Stratégie NR | D9: La stratégie numérique responsable a-t-elle été déclinée dans d'autres documents programmatiques (SPASER, PCAET…) ? | G9: Non | H9: Oui, partiellement | I9: Oui, en grande partie | J9: Oui ils sont totalement inclus
A10: 1 | B10: 1. Stratégie et Gouvernance | C10: Stratégie NR | D10: Avez-vous un budget spécifique dédié pour une stratégie et des actions Numérique Responsable ? | G10: Non | H10: Utilisation de l'enveloppe de la DSI/Service | I10: Enveloppe dédiée dans la direction concernée | J10: Enveloppe dédiée au niveau transverse
A11: 2 | B11: 1. Stratégie et Gouvernance | C11: Stratégie NR | D11: Comment est réparti le budget Numérique responsable (formations, développement de use cases, enablers IT, autres) ?
A12: 3 | B12: 1. Stratégie et Gouvernance | C12: Stratégie NR | D12: Votre stratégie Numérique Responsable a-t-elle permis la mise en place de partenariats, la signature d'accords ou l'attribution de certifications / prix ? | G12: Non | H12: Non mais certaines opportunités ont été identifiées pour la mise en place de partenariats / accords | I12: La collectivité a mis en place des partenariats ou s'est déjà engagée via des accords sur sa stratégie NR | J12: La collectivité a été distinguée par des certifications / prix sur son investissement NR
A13: 3 | B13: 1. Stratégie et Gouvernance | C13: Stratégie NR | D13: Si oui, décrivez les partenariats, accords ou certifications | E13: Question qualitative entretien
A14: 2 | B14: 1. Stratégie et Gouvernance | C14: Stratégie NR | D14: Des objectifs de Numérique responsable sont-ils intégrés à vos rapport annuels ? | G14: Non | H14: Oui, partiellement (inclus dans les objectifs et la stratégie de l'organisation, mais pas détaillé dans la partie comptabilité) | I14: Oui, en grande partie (inclus dans les objectifs et la stratégie de de l'organisation et partiellement inclus dans la partie comptabilité) | J14: Oui ils sont totalement inclus dans les rapports annuels (ils font intégralement partie des bilans financiers consolidés, ils sont définis dans les objectifs de l'organisation et ils ont leur propre partie dans le rapport annuel de l'organisation)
A15: 2 | B15: 1. Stratégie et Gouvernance | C15: Stratégie NR | D15: Si oui, décrivez les éléments essentiels et l'année de mise en oeuvre ? | E15: Question qualitative entretien
A16: 1 | B16: 1. Stratégie et Gouvernance | C16: Org. Interne | D16: Dans votre organisation, cette dimension écologique du numérique est intégrée comme : … | G16: N'est pas intégrée | H16: Une fonction DSI | I16: Une fonction "Transition écologique" attachée au DGS | J16: Une fonction transverse rattachée au DGS
A17: 1 | B17: 1. Stratégie et Gouvernance | C17: Org. Interne | D17: Qui est en charge de porter les sujets Numérique Responsable au sein de votre organisation ? | G17: Personne n'est en charge | H17: Une personne porte ces sujets au sein d'une direction | I17: Une personne/une entité est en charge de l'ensemble des sujets Numérique Responsable à temps partiel | J17: Une ou plusieurs personn(e)s occupent un poste à temps plein dédié au Numérique Responsable
A18: 2 | B18: 1. Stratégie et Gouvernance | C18: Org. Interne | D18: A quel niveau hiérarchique se situe le pôle Numérique Responsable ? | G18: Pas de pôle Numérique Responsable | H18: Le pôle Numérique Responsable n'est pas visible dans la hiérarchie | I18: Le pôle Numérique Responsable est rattaché au niveau d'une Unité Business / Organisationnelle | J18: Le pôle Numérique Responsable est rattaché au niveau du DGS/de la Direction générale
A19: 2 | B19: 1. Stratégie et Gouvernance | C19: Org. Interne | D19: Le responsable numérique responsable participe t-il à des comités de pilotage ? | G19: Non | H19: Oui, en interne de son service | I19: Oui, en interne de sa direction | J19: Oui, en transverse sur l'ensemble de la collectivité
A20: 2 | B20: 1. Stratégie et Gouvernance | C20: Org. Interne | D20: Le pôle Numérique Responsable peut il s'appuyer sur des relais identifiés dans les entités ? | G20: Non | H20: Un groupe de contacts permet de partager quelques informations avec le pôle Numérique Responsable (veille, …) | I20: Des relais diffusent une veille et des bonnes pratiques Numérique Responsable au sein des entités | J20: Des représentants officiels (champions) du numérique responsable sont identifiés dans les différentes entités et ont une charge dédiée à cette thématique
A21: 3 | B21: 1. Stratégie et Gouvernance | C21: Org. Interne | D21: Faites-vous appel à des prestataires spécialisés dans le Numérique Responsable ? | G21: Non | H21: Des prestataires potentiels ont déjà été identifiés | I21: Des discussions ont été engagées avec des prestataires potentiels | J21: Des prestataires ont déjà été sollicités pour accompagner la collectivité
A22: 1 | B22: 1. Stratégie et Gouvernance | C22: Org. Interne | D22: Votre organisation a t-elle mis en place le télétravail hors crise sanitaire ? | G22: Non | J22: Oui
A23: 1 | B23: 1. Stratégie et Gouvernance | C23: Org. Interne | D23: Quelle est la part de télétravailleurs ? | G23: <10% | H23: 10%<X<40% | I23: 40%<X<70% | J23: >70%
A24: 1 | B24: 1. Stratégie et Gouvernance | C24: Org. Interne | D24: Quel est le nombre de jours télétravaillés par mois et par collaborateur en moyenne ? | G24: <4 | H24: 4<X<8 | I24: 8<X<12 | J24: >12
A25: 1 | B25: 1. Stratégie et Gouvernance | C25: Org. Interne | D25: Quelles difficultés avez-vous eu au sujet du télétravail ? (organisation du travail, matériel, sécurité, logiciels, réseau...)
A26: 2 | B26: 1. Stratégie et Gouvernance | C26: Org. Interne | D26: Est-ce que la politique de télétravail mise en place dans l'organisation a prévu une campagne de mesure des impacts environnementaux ? | G26: Non | J26: Oui
A27: 2 | B27: 1. Stratégie et Gouvernance | C27: AVEC/BYOD | D27: Mettez-vous en place une stratégie "AVEC" pour l'équipement informatique type ordinateur portable ? | G27: Non
A28: 2 | B28: 1. Stratégie et Gouvernance | C28: AVEC/BYOD | D28: Mettez-vous en place une stratégie "AVEC" pour l'équipement téléphonique type smartphone ? | G28: Non
A29: 2 | B29: 1. Stratégie et Gouvernance | C29: AVEC/BYOD | D29: En cas d'application d'une stratégie "AVEC", quelle stratégie avez-vous mis en place pour la faire accepter par les agents ?
A30: 1 | B30: 1. Stratégie et Gouvernance | C30: Mesure d'impact environnemental | D30: Souhaitez-vous avoir un outil de suivi et de pilotage de la performance environnementale du SI ? | G30: Non | J30: Oui
A31: 2 | B31: 1. Stratégie et Gouvernance | C31: Mesure d'impact environnemental | D31: Quel est le niveau d’urgence de votre besoin en outils ou méthodologies de mesure ? | E31: Faible / Moyen / élevé
A32: 2 | B32: 1. Stratégie et Gouvernance | C32: Mesure d'impact environnemental | D32: Quelles sont vos priorités ? (choix multiples) | E32: Se faire accompagner / Se former / Outiller / Mesurer / Suivre
A33: 2 | B33: 1. Stratégie et Gouvernance | C33: Mesure d'impact environnemental | D33: Si autres priorités, précisez :
A34: 1 | B34: 1. Stratégie et Gouvernance | C34: Sources | D34: De quelles sources proviennent les bonnes pratiques liées au Numérique Responsable mises en place par la collectivité (réglementation, organismes d'autorité, propres initiatives…)? | G34: La collectivité applique principalement la réglementation | H34: La collectivité s'appuie sur les préconisations d'organismes reconnus comme l'Ademe, le club Green IT… | I34: La collectivité participe à des démarches exploratoires sur certains leviers | J34: La collectivité expérimente des leviers et fait figure de précurseur
A35: 1 | B35: 1. Stratégie et Gouvernance | C35: Stratégie générale | D35: Avez-vous mis en œuvre une stratégie de Smart City ? | G35: Non | H35: Non, c'est un projet | I35: Oui, mais sur des actions isolées | J35: Oui, avec une stratégie globale
A36: 1 | B36: 1. Stratégie et Gouvernance | C36: Territoire | D36: Selon vous qui sont les acteurs en interne ou externe à votre structure, qui peuvent réduire les impacts écologiques du numérique ?
A37: 1 | B37: 1. Stratégie et Gouvernance | C37: Territoire | D37: Avez-vous directement ou indirectement des moyens d'agir sur ces acteurs ?
A38: 1 | B38: 1. Stratégie et Gouvernance | D38: Pourriez-vous fournir des exemples de mesures/projets/initiatives mis en place concernant le Numérique responsable ?

Sheet 2. Mesure
A1: Grille d'entretien | G1: Grille de notation
A2: Niveau | B2: Pilier | C2: Thématique | D2: Question | E2: Types de réponses | F2: Acteur répondant | G2: 1 | H2: 2 | I2: 3 | J2: 4 | K2: 5 | L2: 6
A3: 1 | B3: 2. Mesure | C3: Utilisateurs | D3: Quel est le nombre d'agents de la collectivité concernés par vos services numériques ? | F3: DSI
A4: 1 | B4: 2. Mesure | C4: Equipements | D4: Nombre d'unités centrales | E4: En unités | F4: DSI
A5: 1 | B5: 2. Mesure | C5: Equipements | D5: Nombre de PC portables | E5: En unités | F5: DSI
A6: 2 | B6: 2. Mesure | C6: Equipements | D6: Nombre de tablettes | E6: En unités | F6: DSI
A7: 3 | B7: 2. Mesure | C7: Equipements | D7: Nombre de téléphone IP | E7: En unités | F7: DSI
A8: 1 | B8: 2. Mesure | C8: Equipements | D8: Nombre de smartphones | E8: En unités | F8: DSI
A9: 3 | B9: 2. Mesure | C9: Equipements | D9: Nombre de bornes WIFI | E9: En unités | F9: DSI
A10: 3 | B10: 2. Mesure | C10: Equipements | D10: Nombre d'enceintes | E10: En unités | F10: DSI
A11: 1 | B11: 2. Mesure | C11: Equipements | D11: Nombre écran plat | E11: En unités | F11: DSI
A12: 2 | B12: 2. Mesure | C12: Equipements | D12: Nombre d'écran TV | E12: En unités | F12: DSI
A13: 2 | B13: 2. Mesure | C13: Equipements | D13: Taille moyenne des écrans | E13: en pouces | F13: DSI
A14: 1 | B14: 2. Mesure | C14: Equipements | D14: Nombre imprimantes en réseau | E14: en unité | F14: DSI
A15: 1 | B15: 2. Mesure | C15: Equipements | D15: Nombre imprimantes personnelles | E15: en unité | F15: DSI
... A17: 1 | B17: 2. Mesure | C17: Equipements | D17: Nombre de nouveaux outils / logiciels introduits dans votre organisation par an | E17: En unités | F17: DSI
A18: 1 | B18: 2. Mesure | C18: Equipements | D18: Des outils collaboratifs sont-ils utilisés par les agents ? | G18: Non, la collaboration se fait par mail uniquement | H18: Les agents ont accès à des espaces de stockages partagés | I18: Les agents ont accès à des outils collaboratifs | J18: Les agents ont accès à des outils collaboratifs et sont formés/sensibilisés à une utilisation responsable
A19: 1 | B19: 2. Mesure | C19: Equipements | D19: Quels sont les outils collaboratifs utilisés par vos agents ?
A20: 1 | B20: 2. Mesure | C20: Durée de vie | D20: Quelle est la durée de vie moyenne de vos unités centrales | F20: DSI | G20: <1 an | H20: 1 et 2 ans | I20: 2 et 3 ans | J20: 3 et 5 ans | K20: 5 et 7 ans | L20: >7 ans
A21: 1 | B21: 2. Mesure | C21: Durée de vie | D21: Quelle est la durée de vie moyenne de vos ordinateurs portables ? | F21: DSI | G21: <1 an | H21: 1 et 2 ans | I21: 2 et 3 ans | J21: 3 et 5 ans | K21: 5 et 7 ans | L21: >7 ans
A22: 2 | B22: 2. Mesure | C22: Durée de vie | D22: Quelle est la durée de vie moyenne de vos tablettes | F22: DSI | G22: <1 an | H22: 1 et 2 ans | I22: 2 et 3 ans | J22: 3 et 5 ans | K22: 5 et 7 ans | L22: >7 ans
A23: 2 | B23: 2. Mesure | C23: Durée de vie | D23: Quelle est la durée de vie moyenne de vos imprimantes personnelles | F23: DSI | G23: <1 an | H23: 1 et 2 ans | I23: 2 et 3 ans | J23: 3 et 5 ans | K23: 5 et 7 ans | L23: >7 ans
A24: 2 | B24: 2. Mesure | C24: Durée de vie | D24: Quelle est la durée de vie moyenne de vos imprimantes en réseau | F24: DSI | G24: <1 an | H24: 1 et 2 ans | I24: 2 et 3 ans | J24: 3 et 5 ans | K24: 5 et 7 ans | L24: >7 ans
A25: 2 | B25: 2. Mesure | C25: Durée de vie | D25: Quelle est la durée de vie moyenne de vos serveurs physiques | F25: DSI | G25: <1 an | H25: 1 et 2 ans | I25: 2 et 3 ans | J25: 3 et 5 ans | K25: 5 et 7 ans | L25: >7 ans
A26: 3 | B26: 2. Mesure | C26: Durée de vie | D26: Quelle est la durée de vie moyenne de vos téléphones IP | F26: DSI | G26: <1 an | H26: 1 et 2 ans | I26: 2 et 3 ans | J26: 3 et 5 ans | K26: 5 et 7 ans | L26: >7 ans
A27: 3 | B27: 2. Mesure | C27: Durée de vie | D27: Quelle est la durée de vie moyenne de vos bornes WIFI ? | F27: DSI | G27: <1 an | H27: 1 et 2 ans | I27: 2 et 3 ans | J27: 3 et 5 ans | K27: 5 et 7 ans | L27: >7 ans
A28: 3 | B28: 2. Mesure | C28: Durée de vie | D28: Quelle est la durée de vie moyenne de vos enceintes | F28: DSI | G28: <1 an | H28: 1 et 2 ans | I28: 2 et 3 ans | J28: 3 et 5 ans | K28: 5 et 7 ans | L28: >7 ans
A29: 1 | B29: 2. Mesure | C29: Empreinte environnementale du SI | D29: L'empreinte environnementale de votre SI, ou de votre projet, a-t-elle été évaluée au moins une fois ? | F29: DSI | G29: Non | H29: Une fois | I29: Ponctuellement mais régulièrement | J29: Suivi régulier
A30: 3 | B30: 2. Mesure | C30: Empreinte environnementale du SI | D30: Quels indicateurs sont suivis pour l'évaluation de votre empreinte environnementale du SI ? | E30: Veuillez écrire votre texte | F30: DSI
A31: 3 | B31: 2. Mesure | C31: Empreinte environnementale du SI | D31: Quels référentiels ou base de données environnementaux utilisez-vous pour faire cette évaluation ? | E31: Veuillez écrire votre texte | F31: DSI
A32: 3 | B32: 2. Mesure | C32: Empreinte environnementale du SI | D32: Avez-vous mesuré cette empreinte en interne collectivité ou en ayant recours à un bureau d'étude spécialisé ? | G32: En interne collectivité | H32: En ayant recours à un prestataire
A33: 3 | B33: 2. Mesure | C33: Empreinte environnementale du SI | D33: Utilisez-vous le RGESN ? Le protocole GHG ? | G33: Non, connaît pas | H33: Non, mais connu | I33: Oui, mais pas utilisé | J33: Oui, utilisé
A34: 1 | B34: 2. Mesure | C34: Empreinte environnementale du SI | D34: Etes-vous familiez avec l'Analyse du Cycle de Vie (ACV) ? | G34: Non, connaît pas | H34: Non, mais connu | I34: Oui, mais pas utilisé | J34: Oui, utilisé
A35: 2 | B35: 2. Mesure | C35: Empreinte environnementale du SI | D35: Si vous évaluez l'empreinte environnemental de votre SI, avez-vous une stratégie de mesure basée sur une ACV (analyse du cycle de vie) ? | E35: oui/non/non concernée | F35: DSI | G35: Non, connaît pas | H35: Non, mais connu | I35: Oui, mais pas utilisé | J35: Oui, utilisé
A36: 2 | B36: 2. Mesure | C36: Empreinte environnementale du SI | D36: Si oui, précisez le contenu de cette stratégie avec ACV ? | E36: Veuillez écrire votre texte | F36: DSI
A37: 1 | B37: 2. Mesure | C37: Empreinte environnementale du SI | D37: Avez-vous réalisé un bilan carbone ? | G37: Non | H37: Non, mais souhait de le faire | I37: Oui, mais incomplet et non suivi d'actions | J37: Oui, régulièrement et inséré dans une stratégie de la CT
A38: 1 | B38: 2. Mesure | C38: Empreinte environnementale du SI | D38: Publiez-vous votre BEGES ? | G38: Non
A39: 3 | B39: 2. Mesure | C39: Empreinte environnementale du SI | D39: Evaluez-vous les émissions directes de GES (ou SCOPE 1) ? Émissions directes provenant des installations fixes ou mobiles situées à l’intérieur du périmètre organisationnel. | E39: oui/non | F39: DSI
A40: 3 | B40: 2. Mesure | C40: Empreinte environnementale du SI | D40: Evaluez-vous les émissions à énergie indirectes (ou SCOPE 2) ? Émissions indirectes associées à la production d’électricité, de chaleur ou de vapeur importée pour les activités de l’organisation. | E40: oui/non | F40: DSI
A41: 3 | B41: 2. Mesure | C41: Empreinte environnementale du SI | D41: Evaluez-vous les autres émissions indirectes (ou SCOPE 3) ? Les autres émissions indirectement produites par les activités de l’organisation qui ne sont pas comptabilisées au 2 mais qui sont liées à la chaîne de valeur complète comme par exemple : l’achat de matières premières, fabrication des équipements informatiques, de services ou autres produits, déplacements des salariés, transport amont et aval des marchandises, gestions des déchets générés par les activités de l’organisme, utilisation et fin de vie des produits et services vendus, immobilisation des biens et équipements de productions… | E41: oui/non | F41: DSI
...

Sheet 3. Achat
A1: Grille d'entretien | G1: Grille de notation
A2: Niveau | B2: Pilier | C2: Thématique | D2: Question | E2: Types de réponses | F2: Acteur répondant | G2: 1 | H2: 2 | I2: 3 | J2: 4
A3: 1 | B3: 3. Achat | C3: Achat d'équipements | D3: Une démarche d’achats responsables des équipements numériques est-elle mise en place ? | E3: oui/non | G3: Non | J3: Oui
A4: 2 | B4: 3. Achat | C4: Achat d'équipements | D4: Publiez-vous un SPASER ? | G4: Non, nous ne sommes pas concernés | J4: Oui
A5: 2 | B5: 3. Achat | C5: Achat d'équipements | D5: Si oui, précisez les critères environnementaux retenus et le cas échéant les questions posées sur le volet développement durable ? | E5: Veuillez écrire votre texte
A6: 2 | B6: 3. Achat | C6: Achat d'équipements | D6: Communiquez-vous auprès de vos fournisseurs sur l’importance de la prise en compte des clauses environnementales et sociales dans votre phase de sourcing ? | E6: oui/non
A7: 1 | B7: 3. Achat | C7: Achat d'équipements | D7: Intégrez-vous des clauses environnementales dans vos marchés d'achat d’équipements ? | G7: Non | J7: Oui
A8: 1 | B8: 3. Achat | C8: Achat d'équipements | D8: Si oui, précisez quelle est sa part dans la décision finale | E8: Il est attendu une réponse avec un pourcentage
A9: 3 | B9: 3. Achat | C9: Achat d'équipements | D9: Intégrez-vous des clauses sociales dans vos marchés ? | E9: oui/non
A10: 3 | B10: 3. Achat | C10: Achat d'équipements | D10: Si oui, précisez les critères sociaux retenus ? | E10: Veuillez écrire votre texte
A11: 3 | B11: 3. Achat | C11: Achat d'équipements | D11: Intégrez-vous des clauses environnementales et sociales dans vos appels d’offres de services et prestations intellectuelles ? | E11: oui/non
A12: 3 | B12: 3. Achat | C12: Achat d'équipements | D12: Pouvez vous lister des exemples de clauses environnementales et sociales qui, d'après vous, ont le plus de poids environnemental ? | E12: Veuillez écrire votre texte
A13: 1 | B13: 3. Achat | C13: Achat d'équipements | D13: Dissociez-vous le renouvellement des unités centrales des autres équipements (écran, clavier, souris) ? | G13: Non | J13: Oui
A14: 1 | B14: 3. Achat | C14: Achat d'équipements | D14: Avez-vous un plan d'action pour réduction du nombre d'équipements par personne et par an ? | G14: Non
A15: 1 | B15: 3. Achat | C15: Achat d'équipements | D15: Si oui, quels équipements et quelles actions sont mis en place ? | E15: réponse ouverte
A16: 1 | B16: 3. Achat | C16: Achat d'équipements | D16: Quelle est la part de l'achat de matériel informatique d'occasion ou reconditionné par rapport à l'achat de neuf ? | E16: Il est attendu une réponse avec un pourcentage
A17: 1 | B17: 3. Achat | C17: Achat d'équipements | D17: Si oui, pouvez-nous nous décrire les équipements concernés et les revendeurs retenus ? | E17: réponse ouverte
A18: 3 | B18: 3. Achat | C18: Achat d'équipements | D18: Quelle part de vos copieurs est issue d'une filière de reconditionnement ? | E18: Il est attendu une réponse avec un pourcentage
A19: 3 | B19: 3. Achat | C19: Achat d'équipements | D19: Quelle est la part des cartouches d'impression issue d'une filière de reconditionnement ? | E19: Il est attendu une réponse avec un pourcentage
A20: 3 | B20: 3. Achat | C20: Achat d'équipements | D20: Avez-vous une stratégie d'urbanisation ou d'achat des équipements non IT (climatisation, traitement de l'air, onduleurs…) selon des critères environnementaux ? | E20: oui/non/ne sais pas
A21: 3 | B21: 3. Achat | C21: Achat d'équipements | D21: Si oui, avez-vous des exemples ? | E21: Veuillez écrire votre texte
A22: 2 | B22: 3. Achat | C22: Achat d'équipements | D22: Choisissez-vous un prestataire d'hébergement ou opérateurs datacentres selon des critères de performance environnementale ? | E22: oui/non/ne sais pas
A23: 2 | B23: 3. Achat | C23: Achat d'équipements | D23: Si oui, quelles sont les critères retenus ? | E23: Veuillez écrire votre texte
A24: 2 | B24: 3. Achat | C24: Achat d'équipements | D24: Comment anticipez-vous les nouvelles réglementations sur le sujet (exemple la loi relative à la lutte contre le gaspillage et à l'économie circulaire) ? | E24: Veuillez écrire votre texte
A25: 1 | B25: 3. Achat | C25: Location | D25: Avez-vous mis en place une stratégie de location de matériels plutôt que d'achat ? | E25: oui/non
A26: 2 | B26: 3. Achat | C26: Location | D26: Pouvez-nous nous décrire les équipements concernés par la location, le % par rapport au parc global et les fournisseurs retenus ? | E26: Veuillez écrire votre texte
... A35: 2 | B35: 3. Achat | C35: Labels | D35: Si oui, laquelle ? | E35: Veuillez écrire votre texte
A36: 2 | B36: 3. Achat | C36: Impression | D36: Avez-vous des fournisseurs qui proposent des copieurs reconditionnés ? | G36: Ne sait pas | H36: Non | J36: Oui
A37: 2 | B37: 3. Achat | C37: Impression | D37: Si oui, quels sont les fournisseurs retenus ? | E37: Veuillez écrire votre texte
A38: 3 | B38: 3. Achat | C38: Impression | D38: Quelle part de papier recyclé utilisez-vous ? | E38: Il est attendu une réponse avec un pourcentage
A39: 3 | B39: 3. Achat | C39: Impression | D39: Quels labels de papier recyclé utilisez-vous ? | E39: réponse ouverte

Sheet 4. Conception
A1: Grille d'entretien | G1: Grille de notation
A2: Niveau | B2: Pilier | C2: Thématique | D2: Question | E2: Types de réponses | F2: Acteur répondant | G2: 1 | H2: 2 | I2: 3 | J2: 4
A3: 1 | B3: 4. Conception | C3: Conception | D3: Mettez-vous en œuvre des bonnes pratiques de conception de services numériques ? | G3: Non | H3: Non, mais sensibilisé | I3: Oui, ponctuellement | J3: Oui, généralisé
A4: 1 | B4: 4. Conception | C4: Conception | D4: Quelles sont vos bonnes pratiques de conception de services numériques ? | E4: Veuillez écrire votre texte
A5: 2 | B5: 4. Conception | C5: Conception | D5: Vos bonnes pratiques de conception de services numériques sont-elles liées à l'éco-conception de services numériques ? | G5: Ne sait pas | H5: Non | J5: Oui
A6: 2 | B6: 4. Conception | C6: Conception | D6: Si oui, quels référentiels ou bonnes pratiques utilisez-vous ? | E6: Veuillez écrire votre texte
A7: 1 | B7: 4. Conception | C7: Conception | D7: Une stratégie de gestion des données (durée de conservation et volume stocké) est-elle mise en place ? | G7: Non | J7: Oui
A8: 3 | B8: 4. Conception | C8: Conception | D8: Avez-vous travaillé sur la réduction du temps passé par un agent sur vos services numériques (le temps moyen pour obtenir une information ou faire une démarche) ? | E8: oui/non | G8: Non | J8: Oui
A9: 3 | B9: 4. Conception | C9: Conception | D9: Avez-vous travaillé sur la réduction du temps passé par un usager sur vos services numériques (le temps moyen pour obtenir une information ou faire une démarche) ? | E9: oui/non | G9: Non | J9: Oui
A10: 3 | B10: 4. Conception | C10: Conception | D10: Si oui, comment ? | E10: Veuillez écrire votre texte
A11: 1 | B11: 4. Conception | C11: Conception | D11: Quelle est la part de solutions open-source dans vos projets ? | E11: % | G11: <10% | H11: 10%<X<40% | I11: 40%<X<70% | J11: >70%
A12: 3 | B12: 4. Conception | C12: Conception | D12: Si vous en avez la responsabilité, concevez-vous une charte graphique responsable ? | G12: Non concerné | H12: Non | I12: En projet | J12: Oui, existante
A13: 3 | B13: 4. Conception | C13: Conception | D13: Si oui, avez-vous des exemples de points d'attention lors de la conception de charte graphique responsable ? | E13: Veuillez écrire votre texte
A14: 1 | B14: 4. Conception | C14: Conception | D14: Mobilisez-vous un chef de produit sur la conception de vos services numériques ? | G14: Non | H14: Parfois | I14: Souvent | J14: Toujours
A15: 1 | B15: 4. Conception | C15: Conception | D15: Mobilisez-vous un ou plusieurs designers UX sur la conception de vos services numériques ? | G15: Non | H15: Parfois | I15: Souvent | J15: Toujours
A16: 1 | B16: 4. Conception | C16: Conception | D16: Mobilisez-vous un chercheur usager sur la conception de vos services numériques ? | G16: Non | H16: Parfois | I16: Souvent | J16: Toujours
A17: 1 | B17: 4. Conception | C17: Conception | D17: Mobilisez-vous un expert accessibilité sur la conception de vos services numériques ? | G17: Non | H17: Parfois | I17: Souvent | J17: Toujours
A18: 2 | B18: 4. Conception | C18: Conception | D18: Avez-vous besoin d'un chef de produit, expert accessibilité, designer UX ou chercheur usager ? | G18: Non | J18: Oui
A19: 2 | B19: 4. Conception | C19: Conception | D19: Le RGAA est-il mis en œuvre ? | G19: Non | J19: Oui
A20: 2 | B20: 4. Conception | C20: Conception | D20: Si oui, avez-vous des exemples de bonnes pratiques mises en place ou un projet exemplaire lié à la mise en œuvre du RGAA ? | E20: Veuillez écrire votre texte
A21: 2 | B21: 4. Conception | C21: Conception | D21: La conformité au RGPD est-elle systématiquement mise en place ? | G21: Non | J21: Oui
A22: 2 | B22: 4. Conception | C22: Conception | D22: Si oui, comment ? | E22: Veuillez écrire votre texte
A23: 3 | B23: 4. Conception | C23: Méthodes de conception | D23: Quelle méthode de développement de logiciel utilisez-vous ? (Cycle en V, Scrum, Safe…) | E23: Veuillez écrire votre texte
A24: 1 | B24: 4. Conception | C24: Méthodes de conception | D24: Les usagers finaux (citoyens, agents, etc) sont-ils impliqués dans le processus de conception de vos services numériques ? | G24: Non | H24: Parfois | I24: Souvent | J24: Toujours
